2018-08-27 17:32:02 [scrapy.utils.log] INFO: Scrapy 1.5.1 started (bot: newsbot)
2018-08-27 17:32:02 [scrapy.utils.log] INFO: Versions: lxml 4.2.4.0, libxml2 2.9.8, cssselect 1.0.3, parsel 1.5.0, w3lib 1.19.0, Twisted 18.7.0, Python 3.6.3 (default, Aug 26 2018, 16:47:54) - [GCC 4.4.7 20120313 (Red Hat 4.4.7-23)], pyOpenSSL 18.0.0 (OpenSSL 1.1.0i  14 Aug 2018), cryptography 2.3.1, Platform Linux-2.6.32-754.3.5.el6.x86_64-x86_64-with-centos-6.10-Final
2018-08-27 17:32:02 [scrapy.crawler] INFO: Overridden settings: {'BOT_NAME': 'newsbot', 'CONCURRENT_REQUESTS_PER_IP': 1, 'DOWNLOAD_DELAY': 0.5, 'DOWNLOAD_TIMEOUT': 100, 'NEWSPIDER_MODULE': 'newsbot.spiders', 'ROBOTSTXT_OBEY': True, 'SPIDER_MODULES': ['newsbot.spiders']}
2018-08-27 17:32:02 [scrapy.middleware] INFO: Enabled extensions:
['scrapy.extensions.corestats.CoreStats',
 'scrapy.extensions.telnet.TelnetConsole',
 'scrapy.extensions.memusage.MemoryUsage',
 'scrapy.extensions.logstats.LogStats']
2018-08-27 17:32:02 [scrapy.middleware] INFO: Enabled downloader middlewares:
['scrapy.downloadermiddlewares.robotstxt.RobotsTxtMiddleware',
 'scrapy.downloadermiddlewares.httpauth.HttpAuthMiddleware',
 'scrapy.downloadermiddlewares.downloadtimeout.DownloadTimeoutMiddleware',
 'scrapy.downloadermiddlewares.defaultheaders.DefaultHeadersMiddleware',
 'scrapy.downloadermiddlewares.useragent.UserAgentMiddleware',
 'scrapy.downloadermiddlewares.retry.RetryMiddleware',
 'scrapy.downloadermiddlewares.redirect.MetaRefreshMiddleware',
 'scrapy.downloadermiddlewares.httpcompression.HttpCompressionMiddleware',
 'scrapy.downloadermiddlewares.redirect.RedirectMiddleware',
 'scrapy.downloadermiddlewares.cookies.CookiesMiddleware',
 'scrapy.downloadermiddlewares.httpproxy.HttpProxyMiddleware',
 'scrapy.downloadermiddlewares.stats.DownloaderStats']
2018-08-27 17:32:02 [scrapy.middleware] INFO: Enabled spider middlewares:
['scrapy.spidermiddlewares.httperror.HttpErrorMiddleware',
 'scrapy.spidermiddlewares.offsite.OffsiteMiddleware',
 'scrapy.spidermiddlewares.referer.RefererMiddleware',
 'scrapy.spidermiddlewares.urllength.UrlLengthMiddleware',
 'scrapy.spidermiddlewares.depth.DepthMiddleware']
2018-08-27 17:32:02 [scrapy.middleware] INFO: Enabled item pipelines:
['newsbot.pipelines.NewsbotPipeline']
2018-08-27 17:32:02 [scrapy.core.engine] INFO: Spider opened
2018-08-27 17:32:02 [scrapy.extensions.logstats] INFO: Crawled 0 pages (at 0 pages/min), scraped 0 items (at 0 items/min)
2018-08-27 17:32:02 [scrapy.extensions.telnet] DEBUG: Telnet console listening on 127.0.0.1:6023
2018-08-27 17:32:02 [scrapy.core.engine] DEBUG: Crawled (200) <GET https://nba.udn.com/robots.txt> (referer: None)
2018-08-27 17:32:02 [scrapy.core.engine] DEBUG: Crawled (200) <GET https://nba.udn.com/nba/index?gr=www> (referer: None)
2018-08-27 17:32:02 [scrapy.core.scraper] ERROR: Error processing {'body': '從上季陷入傷勢問題後到現在，雷納德（Kawhi Leonard）的狀況一直都是謎，在沒有公開打球或...',
 'headline': '健康狀態100%恢復？ 傳雷納德訓練成效佳',
 'link': 'https://nba.udn.com/nba/story/6780/3332878',
 'photo': 'https://pgw.udn.com.tw/gw/photo.php?u=https://uc.udn.com.tw/photo/2018/08/27/99/5185462.jpg&x=0&y=0&sw=0&sh=0&sl=W&fw=200&exp=3600'}
Traceback (most recent call last):
  File "/usr/local/lib/python3.6/site-packages/django/db/backends/utils.py", line 85, in _execute
    return self.cursor.execute(sql, params)
  File "/usr/local/lib/python3.6/site-packages/django/db/backends/sqlite3/base.py", line 296, in execute
    return Database.Cursor.execute(self, query, params)
sqlite3.IntegrityError: UNIQUE constraint failed: top_news.link

The above exception was the direct cause of the following exception:

Traceback (most recent call last):
  File "/usr/local/lib/python3.6/site-packages/twisted/internet/defer.py", line 654, in _runCallbacks
    current.result = callback(current.result, *args, **kw)
  File "/var/www/my_venv/nicetomeetyoutoo/bots/newsbot/newsbot/pipelines.py", line 11, in process_item
    item.save()
  File "/usr/local/lib/python3.6/site-packages/scrapy_djangoitem/__init__.py", line 35, in save
    self.instance.save()
  File "/usr/local/lib/python3.6/site-packages/django/db/models/base.py", line 717, in save
    force_update=force_update, update_fields=update_fields)
  File "/usr/local/lib/python3.6/site-packages/django/db/models/base.py", line 747, in save_base
    updated = self._save_table(raw, cls, force_insert, force_update, using, update_fields)
  File "/usr/local/lib/python3.6/site-packages/django/db/models/base.py", line 830, in _save_table
    result = self._do_insert(cls._base_manager, using, fields, update_pk, raw)
  File "/usr/local/lib/python3.6/site-packages/django/db/models/base.py", line 868, in _do_insert
    using=using, raw=raw)
  File "/usr/local/lib/python3.6/site-packages/django/db/models/manager.py", line 82, in manager_method
    return getattr(self.get_queryset(), name)(*args, **kwargs)
  File "/usr/local/lib/python3.6/site-packages/django/db/models/query.py", line 1133, in _insert
    return query.get_compiler(using=using).execute_sql(return_id)
  File "/usr/local/lib/python3.6/site-packages/django/db/models/sql/compiler.py", line 1285, in execute_sql
    cursor.execute(sql, params)
  File "/usr/local/lib/python3.6/site-packages/django/db/backends/utils.py", line 100, in execute
    return super().execute(sql, params)
  File "/usr/local/lib/python3.6/site-packages/django/db/backends/utils.py", line 68, in execute
    return self._execute_with_wrappers(sql, params, many=False, executor=self._execute)
  File "/usr/local/lib/python3.6/site-packages/django/db/backends/utils.py", line 77, in _execute_with_wrappers
    return executor(sql, params, many, context)
  File "/usr/local/lib/python3.6/site-packages/django/db/backends/utils.py", line 85, in _execute
    return self.cursor.execute(sql, params)
  File "/usr/local/lib/python3.6/site-packages/django/db/utils.py", line 89, in __exit__
    raise dj_exc_value.with_traceback(traceback) from exc_value
  File "/usr/local/lib/python3.6/site-packages/django/db/backends/utils.py", line 85, in _execute
    return self.cursor.execute(sql, params)
  File "/usr/local/lib/python3.6/site-packages/django/db/backends/sqlite3/base.py", line 296, in execute
    return Database.Cursor.execute(self, query, params)
django.db.utils.IntegrityError: UNIQUE constraint failed: top_news.link
2018-08-27 17:32:02 [scrapy.core.scraper] ERROR: Error processing {'body': '曾拿下3次助攻王的朗多（Rajon Rondo），在今年夏天以一年900萬美元的合約轉戰湖人，他與...',
 'headline': '朗多擔任導師 布萊恩：鮑爾可以學到很多',
 'link': 'https://nba.udn.com/nba/story/6780/3333003',
 'photo': 'https://pgw.udn.com.tw/gw/photo.php?u=https://uc.udn.com.tw/photo/2018/08/27/99/5185727.jpg&x=0&y=0&sw=0&sh=0&sl=W&fw=200&exp=3600'}
Traceback (most recent call last):
  File "/usr/local/lib/python3.6/site-packages/django/db/backends/utils.py", line 85, in _execute
    return self.cursor.execute(sql, params)
  File "/usr/local/lib/python3.6/site-packages/django/db/backends/sqlite3/base.py", line 296, in execute
    return Database.Cursor.execute(self, query, params)
sqlite3.IntegrityError: UNIQUE constraint failed: top_news.link

The above exception was the direct cause of the following exception:

Traceback (most recent call last):
  File "/usr/local/lib/python3.6/site-packages/twisted/internet/defer.py", line 654, in _runCallbacks
    current.result = callback(current.result, *args, **kw)
  File "/var/www/my_venv/nicetomeetyoutoo/bots/newsbot/newsbot/pipelines.py", line 11, in process_item
    item.save()
  File "/usr/local/lib/python3.6/site-packages/scrapy_djangoitem/__init__.py", line 35, in save
    self.instance.save()
  File "/usr/local/lib/python3.6/site-packages/django/db/models/base.py", line 717, in save
    force_update=force_update, update_fields=update_fields)
  File "/usr/local/lib/python3.6/site-packages/django/db/models/base.py", line 747, in save_base
    updated = self._save_table(raw, cls, force_insert, force_update, using, update_fields)
  File "/usr/local/lib/python3.6/site-packages/django/db/models/base.py", line 830, in _save_table
    result = self._do_insert(cls._base_manager, using, fields, update_pk, raw)
  File "/usr/local/lib/python3.6/site-packages/django/db/models/base.py", line 868, in _do_insert
    using=using, raw=raw)
  File "/usr/local/lib/python3.6/site-packages/django/db/models/manager.py", line 82, in manager_method
    return getattr(self.get_queryset(), name)(*args, **kwargs)
  File "/usr/local/lib/python3.6/site-packages/django/db/models/query.py", line 1133, in _insert
    return query.get_compiler(using=using).execute_sql(return_id)
  File "/usr/local/lib/python3.6/site-packages/django/db/models/sql/compiler.py", line 1285, in execute_sql
    cursor.execute(sql, params)
  File "/usr/local/lib/python3.6/site-packages/django/db/backends/utils.py", line 100, in execute
    return super().execute(sql, params)
  File "/usr/local/lib/python3.6/site-packages/django/db/backends/utils.py", line 68, in execute
    return self._execute_with_wrappers(sql, params, many=False, executor=self._execute)
  File "/usr/local/lib/python3.6/site-packages/django/db/backends/utils.py", line 77, in _execute_with_wrappers
    return executor(sql, params, many, context)
  File "/usr/local/lib/python3.6/site-packages/django/db/backends/utils.py", line 85, in _execute
    return self.cursor.execute(sql, params)
  File "/usr/local/lib/python3.6/site-packages/django/db/utils.py", line 89, in __exit__
    raise dj_exc_value.with_traceback(traceback) from exc_value
  File "/usr/local/lib/python3.6/site-packages/django/db/backends/utils.py", line 85, in _execute
    return self.cursor.execute(sql, params)
  File "/usr/local/lib/python3.6/site-packages/django/db/backends/sqlite3/base.py", line 296, in execute
    return Database.Cursor.execute(self, query, params)
django.db.utils.IntegrityError: UNIQUE constraint failed: top_news.link
2018-08-27 17:32:02 [scrapy.core.scraper] ERROR: Error processing {'body': '勇士總教練柯爾（Steve Kerr）近日接受採訪時表示，詹姆斯（LeBron James）、在2...',
 'headline': '球員掌握主動權 柯爾：詹皇改變巨星思維',
 'link': 'https://nba.udn.com/nba/story/6780/3333168',
 'photo': 'https://pgw.udn.com.tw/gw/photo.php?u=https://uc.udn.com.tw/photo/2018/08/27/99/5186026.jpg&x=0&y=0&sw=0&sh=0&sl=W&fw=292&exp=3600'}
Traceback (most recent call last):
  File "/usr/local/lib/python3.6/site-packages/django/db/backends/utils.py", line 85, in _execute
    return self.cursor.execute(sql, params)
  File "/usr/local/lib/python3.6/site-packages/django/db/backends/sqlite3/base.py", line 296, in execute
    return Database.Cursor.execute(self, query, params)
sqlite3.IntegrityError: UNIQUE constraint failed: top_news.link

The above exception was the direct cause of the following exception:

Traceback (most recent call last):
  File "/usr/local/lib/python3.6/site-packages/twisted/internet/defer.py", line 654, in _runCallbacks
    current.result = callback(current.result, *args, **kw)
  File "/var/www/my_venv/nicetomeetyoutoo/bots/newsbot/newsbot/pipelines.py", line 11, in process_item
    item.save()
  File "/usr/local/lib/python3.6/site-packages/scrapy_djangoitem/__init__.py", line 35, in save
    self.instance.save()
  File "/usr/local/lib/python3.6/site-packages/django/db/models/base.py", line 717, in save
    force_update=force_update, update_fields=update_fields)
  File "/usr/local/lib/python3.6/site-packages/django/db/models/base.py", line 747, in save_base
    updated = self._save_table(raw, cls, force_insert, force_update, using, update_fields)
  File "/usr/local/lib/python3.6/site-packages/django/db/models/base.py", line 830, in _save_table
    result = self._do_insert(cls._base_manager, using, fields, update_pk, raw)
  File "/usr/local/lib/python3.6/site-packages/django/db/models/base.py", line 868, in _do_insert
    using=using, raw=raw)
  File "/usr/local/lib/python3.6/site-packages/django/db/models/manager.py", line 82, in manager_method
    return getattr(self.get_queryset(), name)(*args, **kwargs)
  File "/usr/local/lib/python3.6/site-packages/django/db/models/query.py", line 1133, in _insert
    return query.get_compiler(using=using).execute_sql(return_id)
  File "/usr/local/lib/python3.6/site-packages/django/db/models/sql/compiler.py", line 1285, in execute_sql
    cursor.execute(sql, params)
  File "/usr/local/lib/python3.6/site-packages/django/db/backends/utils.py", line 100, in execute
    return super().execute(sql, params)
  File "/usr/local/lib/python3.6/site-packages/django/db/backends/utils.py", line 68, in execute
    return self._execute_with_wrappers(sql, params, many=False, executor=self._execute)
  File "/usr/local/lib/python3.6/site-packages/django/db/backends/utils.py", line 77, in _execute_with_wrappers
    return executor(sql, params, many, context)
  File "/usr/local/lib/python3.6/site-packages/django/db/backends/utils.py", line 85, in _execute
    return self.cursor.execute(sql, params)
  File "/usr/local/lib/python3.6/site-packages/django/db/utils.py", line 89, in __exit__
    raise dj_exc_value.with_traceback(traceback) from exc_value
  File "/usr/local/lib/python3.6/site-packages/django/db/backends/utils.py", line 85, in _execute
    return self.cursor.execute(sql, params)
  File "/usr/local/lib/python3.6/site-packages/django/db/backends/sqlite3/base.py", line 296, in execute
    return Database.Cursor.execute(self, query, params)
django.db.utils.IntegrityError: UNIQUE constraint failed: top_news.link
2018-08-27 17:32:02 [scrapy.core.engine] INFO: Closing spider (finished)
2018-08-27 17:32:02 [scrapy.statscollectors] INFO: Dumping Scrapy stats:
{'downloader/request_bytes': 446,
 'downloader/request_count': 2,
 'downloader/request_method_count/GET': 2,
 'downloader/response_bytes': 18666,
 'downloader/response_count': 2,
 'downloader/response_status_count/200': 2,
 'finish_reason': 'finished',
 'finish_time': datetime.datetime(2018, 8, 27, 17, 32, 2, 660344),
 'log_count/DEBUG': 3,
 'log_count/ERROR': 3,
 'log_count/INFO': 7,
 'memusage/max': 55164928,
 'memusage/startup': 55164928,
 'response_received_count': 2,
 'scheduler/dequeued': 1,
 'scheduler/dequeued/memory': 1,
 'scheduler/enqueued': 1,
 'scheduler/enqueued/memory': 1,
 'start_time': datetime.datetime(2018, 8, 27, 17, 32, 2, 410750)}
2018-08-27 17:32:02 [scrapy.core.engine] INFO: Spider closed (finished)
